Workbook

Sheet Customers
A1: CustomerKey | B1: Prefix | C1: FirstName | D1: LastName | E1: FullName | F1: BirthDate | G1: Year of Birth | H1: MaritalStatus | I1: Marital Status Full | J1: Gender | K1: Gender Full | L1: EmailAddress | M1: Username | N1: AnnualIncome | O1: Wealth Category | P1: TotalChildren | Q1: EducationLevel | R1: Occupation | S1: HomeOwner
A2: 13001 | B2: MR. | C2: CLARENCE | D2: ZHANG | E2: =B2 &" "&C2&" "&D2 -> MR. CLARENCE ZHANG | F2: 25452 | G2: =YEAR(F2) -> 1969 | H2: S | I2: =IF(H2="M","Married","Single") -> Single | J2: M | K2: =IF(J2="M","Male","Female") -> Male | L2: clarence37@adventure-works.com | M2: =LEFT(L2,SEARCH("@",L2)-1) -> clarence37 | N2: 130000 | O2: =IF(N2>=150000,"Wealthy",IF(N2>=100000,"Rich",IF(N2>=50000,"Average","Poor"))) -> Rich | P2: 1 | Q2: Graduate Degree | R2: Management | S2: Y
A3: 13002 | B3: MR. | C3: ROGER | D3: CAI | E3: =B3 &" "&C3&" "&D3 -> MR. ROGER CAI | F3: 24706 | G3: =YEAR(F3) -> 1967 | H3: M | I3: =IF(H3="M","Married","Single") -> Married | J3: M | K3: =IF(J3="M","Male","Female") -> Male | L3: roger25@adventure-works.com | M3: =LEFT(L3,SEARCH("@",L3)-1) -> roger25 | N3: 80000 | O3: =IF(N3>=150000,"Wealthy",IF(N3>=100000,"Rich",IF(N3>=50000,"Average","Poor"))) -> Average | P3: 5 | Q3: Graduate Degree | R3: Management | S3: N
A4: 13003 | B4: MRS. | C4: JILL | D4: HERNANDEZ | E4: =B4 &" "&C4&" "&D4 -> MRS. JILL HERNANDEZ | F4: 24492 | G4: =YEAR(F4) -> 1967 | H4: M | I4: =IF(H4="M","Married","Single") -> Married | J4: F | K4: =IF(J4="M","Male","Female") -> Female | L4: jill11@adventure-works.com | M4: =LEFT(L4,SEARCH("@",L4)-1) -> jill11 | N4: 80000 | O4: =IF(N4>=150000,"Wealthy",IF(N4>=100000,"Rich",IF(N4>=50000,"Average","Poor"))) -> Average | P4: 5 | Q4: Graduate Degree | R4: Management | S4: Y
A5: 13004 | B5: MR. | C5: RANDY | D5: CHEN | E5: =B5 &" "&C5&" "&D5 -> MR. RANDY CHEN | F5: 24596 | G5: =YEAR(F5) -> 1967 | H5: M | I5: =IF(H5="M","Married","Single") -> Married | J5: M | K5: =IF(J5="M","Male","Female") -> Male | L5: randy4@adventure-works.com | M5: =LEFT(L5,SEARCH("@",L5)-1) -> randy4 | N5: 80000 | O5: =IF(N5>=150000,"Wealthy",IF(N5>=100000,"Rich",IF(N5>=50000,"Average","Poor"))) -> Average | P5: 5 | Q5: Graduate Degree | R5: Management | S5: N
A6: 13005 | B6: MRS. | C6: DESIREE | D6: ALVAREZ | E6: =B6 &" "&C6&" "&D6 -> MRS. DESIREE ALVAREZ | F6: 24334 | G6: =YEAR(F6) -> 1966 | H6: M | I6: =IF(H6="M","Married","Single") -> Married | J6: F | K6: =IF(J6="M","Male","Female") -> Female | L6: desiree0@adventure-works.com | M6: =LEFT(L6,SEARCH("@",L6)-1) -> desiree0 | N6: 80000 | O6: =IF(N6>=150000,"Wealthy",IF(N6>=100000,"Rich",IF(N6>=50000,"Average","Poor"))) -> Average | P6: 5 | Q6: Graduate Degree | R6: Management | S6: N
A7: 13006 | B7: MS. | C7: WHITNEY | D7: RANA | E7: =B7 &" "&C7&" "&D7 -> MS. WHITNEY RANA | F7: 24218 | G7: =YEAR(F7) -> 1966 | H7: S | I7: =IF(H7="M","Married","Single") -> Single | J7: F | K7: =IF(J7="M","Male","Female") -> Female | L7: whitney10@adventure-works.com | M7: =LEFT(L7,SEARCH("@",L7)-1) -> whitney10 | N7: 90000 | O7: =IF(N7>=150000,"Wealthy",IF(N7>=100000,"Rich",IF(N7>=50000,"Average","Poor"))) -> Average | P7: 0 | Q7: Bachelors | R7: Professional | S7: N
A8: 13007 | B8: MRS. | C8: BROOKE | D8: WARD | E8: =B8 &" "&C8&" "&D8 -> MRS. BROOKE WARD | F8: 24020 | G8: =YEAR(F8) -> 1965 | H8: S | I8: =IF(H8="M","Married","Single") -> Single | J8: F | K8: =IF(J8="M","Male","Female") -> Female | L8: brooke11@adventure-works.com | M8: =LEFT(L8,SEARCH("@",L8)-1) -> brooke11 | N8: 60000 | O8: =IF(N8>=150000,"Wealthy",IF(N8>=100000,"Rich",IF(N8>=50000,"Average","Poor"))) -> Average | P8: 2 | Q8: Bachelors | R8: Professional | S8: N
A9: 13008 | B9: MR. | C9: ALBERTO | D9: MUÑOZ | E9: =B9 &" "&C9&" "&D9 -> MR. ALBERTO MUÑOZ | F9: 23932 | G9: =YEAR(F9) -> 1965 | H9: M | I9: =IF(H9="M","Married","Single") -> Married | J9: M | K9: =IF(J9="M","Male","Female") -> Male | L9: alberto8@adventure-works.com | M9: =LEFT(L9,SEARCH("@",L9)-1) -> alberto8 | N9: 60000 | O9: =IF(N9>=150000,"Wealthy",IF(N9>=100000,"Rich",IF(N9>=50000,"Average","Poor"))) -> Average | P9: 3 | Q9: Bachelors | R9: Professional | S9: Y
A10: 13009 | B10: MRS. | C10: MINDY | D10: SHE | E10: =B10 &" "&C10&" "&D10 -> MRS. MINDY SHE | F10: 23812 | G10: =YEAR(F10) -> 1965 | H10: M | I10: =IF(H10="M","Married","Single") -> Married | J10: F | K10: =IF(J10="M","Male","Female") -> Female | L10: mindy4@adventure-works.com | M10: =LEFT(L10,SEARCH("@",L10)-1) -> mindy4 | N10: 60000 | O10: =IF(N10>=150000,"Wealthy",IF(N10>=100000,"Rich",IF(N10>=50000,"Average","Poor"))) -> Average | P10: 3 | Q10: Bachelors | R10: Professional | S10: Y
A11: 13010 | B11: MRS. | C11: ERICA | D11: YE | E11: =B11 &" "&C11&" "&D11 -> MRS. ERICA YE | F11: 23970 | G11: =YEAR(F11) -> 1965 | H11: M | I11: =IF(H11="M","Married","Single") -> Married | J11: F | K11: =IF(J11="M","Male","Female") -> Female | L11: erica9@adventure-works.com | M11: =LEFT(L11,SEARCH("@",L11)-1) -> erica9 | N11: 60000 | O11: =IF(N11>=150000,"Wealthy",IF(N11>=100000,"Rich",IF(N11>=50000,"Average","Poor"))) -> Average | P11: 3 | Q11: Bachelors | R11: Professional | S11: Y
A12: 13011 | B12: MS. | C12: ANNE | D12: ORTEGA | E12: =B12 &" "&C12&" "&D12 -> MS. ANNE ORTEGA | F12: 23866 | G12: =YEAR(F12) -> 1965 | H12: S | I12: =IF(H12="M","Married","Single") -> Single | J12: F | K12: =IF(J12="M","Male","Female") -> Female | L12: anne22@adventure-works.com | M12: =LEFT(L12,SEARCH("@",L12)-1) -> anne22 | N12: 70000 | O12: =IF(N12>=150000,"Wealthy",IF(N12>=100000,"Rich",IF(N12>=50000,"Average","Poor"))) -> Average | P12: 0 | Q12: Bachelors | R12: Professional | S12: N
A13: 13012 | B13: MS. | C13: KRYSTAL | D13: HU | E13: =B13 &" "&C13&" "&D13 -> MS. KRYSTAL HU | F13: 24009 | G13: =YEAR(F13) -> 1965 | H13: S | I13: =IF(H13="M","Married","Single") -> Single | J13: F | K13: =IF(J13="M","Male","Female") -> Female | L13: krystal20@adventure-works.com | M13: =LEFT(L13,SEARCH("@",L13)-1) -> krystal20 | N13: 70000 | O13: =IF(N13>=150000,"Wealthy",IF(N13>=100000,"Rich",IF(N13>=50000,"Average","Poor"))) -> Average | P13: 0 | Q13: Bachelors | R13: Professional | S13: N
... A137: 13137 | B137: MRS. | C137: JACQUELINE | D137: SIMMONS | E137: =B137 &" "&C137&" "&D137 -> MRS. JACQUELINE SIMMONS | F137: 21955 | G137: =YEAR(F137) -> 1960 | H137: M | I137: =IF(H137="M","Married","Single") -> Married | J137: F | K137: =IF(J137="M","Male","Female") -> Female | L137: jacqueline16@adventure-works.com | M137: =LEFT(L137,SEARCH("@",L137)-1) -> jacqueline16 | N137: 70000 | O137: =IF(N137>=150000,"Wealthy",IF(N137>=100000,"Rich",IF(N137>=50000,"Average","Poor"))) -> Average | P137: 5 | Q137: Partial College | R137: Skilled Manual | S137: N
A138: 13138 | C138: TERESA | D138: ALONSO | E138: =B138 &" "&C138&" "&D138 -> TERESA ALONSO | F138: 22078 | G138: =YEAR(F138) -> 1960 | H138: M | I138: =IF(H138="M","Married","Single") -> Married | J138: NA | K138: =IF(J138="M","Male","Female") -> Female | L138: teresa8@adventure-works.com | M138: =LEFT(L138,SEARCH("@",L138)-1) -> teresa8 | N138: 70000 | O138: =IF(N138>=150000,"Wealthy",IF(N138>=100000,"Rich",IF(N138>=50000,"Average","Poor"))) -> Average | P138: 5 | Q138: Partial College | R138: Skilled Manual | S138: Y
A139: 13139 | B139: MRS. | C139: CARMEN | D139: PEREZ | E139: =B139 &" "&C139&" "&D139 -> MRS. CARMEN PEREZ | F139: 20494 | G139: =YEAR(F139) -> 1956 | H139: S | I139: =IF(H139="M","Married","Single") -> Single | J139: F | K139: =IF(J139="M","Male","Female") -> Female | L139: carmen3@adventure-works.com | M139: =LEFT(L139,SEARCH("@",L139)-1) -> carmen3 | N139: 70000 | O139: =IF(N139>=150000,"Wealthy",IF(N139>=100000,"Rich",IF(N139>=50000,"Average","Poor"))) -> Average | P139: 1 | Q139: Partial College | R139: Skilled Manual | S139: N
A140: 13141 | B140: MR. | C140: WALTER | D140: HERNANDEZ | E140: =B140 &" "&C140&" "&D140 -> MR. WALTER HERNANDEZ | F140: 19640 | G140: =YEAR(F140) -> 1953 | H140: M | I140: =IF(H140="M","Married","Single") -> Married | J140: M | K140: =IF(J140="M","Male","Female") -> Male | L140: walter16@adventure-works.com | M140: =LEFT(L140,SEARCH("@",L140)-1) -> walter16 | N140: 40000 | O140: =IF(N140>=150000,"Wealthy",IF(N140>=100000,"Rich",IF(N140>=50000,"Average","Poor"))) -> Poor | P140: 2 | Q140: Bachelors | R140: Management | S140: Y
A141: 13142 | B141: MR. | C141: XAVIER | D141: MOORE | E141: =B141 &" "&C141&" "&D141 -> MR. XAVIER MOORE | F141: 27476 | G141: =YEAR(F141) -> 1975 | H141: M | I141: =IF(H141="M","Married","Single") -> Married | J141: M | K141: =IF(J141="M","Male","Female") -> Male | L141: xavier6@adventure-works.com | M141: =LEFT(L141,SEARCH("@",L141)-1) -> xavier6 | N141: 40000 | O141: =IF(N141>=150000,"Wealthy",IF(N141>=100000,"Rich",IF(N141>=50000,"Average","Poor"))) -> Poor | P141: 0 | Q141: High School | R141: Skilled Manual | S141: Y
A142: 13143 | B142: MS. | C142: HANNAH | D142: JACKSON | E142: =B142 &" "&C142&" "&D142 -> MS. HANNAH JACKSON | F142: 27431 | G142: =YEAR(F142) -> 1975 | H142: M | I142: =IF(H142="M","Married","Single") -> Married | J142: F | K142: =IF(J142="M","Male","Female") -> Female | L142: hannah11@adventure-works.com | M142: =LEFT(L142,SEARCH("@",L142)-1) -> hannah11 | N142: 40000 | O142: =IF(N142>=150000,"Wealthy",IF(N142>=100000,"Rich",IF(N142>=50000,"Average","Poor"))) -> Poor | P142: 0 | Q142: High School | R142: Skilled Manual | S142: Y
A143: 13144 | B143: MS. | C143: DESTINY | D143: STEWART | E143: =B143 &" "&C143&" "&D143 -> MS. DESTINY STEWART | F143: 27999 | G143: =YEAR(F143) -> 1976 | H143: S | I143: =IF(H143="M","Married","Single") -> Single | J143: F | K143: =IF(J143="M","Male","Female") -> Female | L143: destiny23@adventure-works.com | M143: =LEFT(L143,SEARCH("@",L143)-1) -> destiny23 | N143: 40000 | O143: =IF(N143>=150000,"Wealthy",IF(N143>=100000,"Rich",IF(N143>=50000,"Average","Poor"))) -> Poor | P143: 0 | Q143: High School | R143: Skilled Manual | S143: N
A144: 13145 | B144: MR. | C144: GILBERT | D144: XU | E144: =B144 &" "&C144&" "&D144 -> MR. GILBERT XU | F144: 27781 | G144: =YEAR(F144) -> 1976 | H144: M | I144: =IF(H144="M","Married","Single") -> Married | J144: M | K144: =IF(J144="M","Male","Female") -> Male | L144: gilbert9@adventure-works.com | M144: =LEFT(L144,SEARCH("@",L144)-1) -> gilbert9 | N144: 40000 | O144: =IF(N144>=150000,"Wealthy",IF(N144>=100000,"Rich",IF(N144>=50000,"Average","Poor"))) -> Poor | P144: 0 | Q144: High School | R144: Skilled Manual | S144: Y
A145: 13146 | B145: MS. | C145: GABRIELLA | D145: RAMIREZ | E145: =B145 &" "&C145&" "&D145 -> MS. GABRIELLA RAMIREZ | F145: 27895 | G145: =YEAR(F145) -> 1976 | H145: S | I145: =IF(H145="M","Married","Single") -> Single | J145: F | K145: =IF(J145="M","Male","Female") -> Female | L145: gabriella4@adventure-works.com | M145: =LEFT(L145,SEARCH("@",L145)-1) -> gabriella4 | N145: 40000 | O145: =IF(N145>=150000,"Wealthy",IF(N145>=100000,"Rich",IF(N145>=50000,"Average","Poor"))) -> Poor | P145: 0 | Q145: High School | R145: Skilled Manual | S145: N
A146: 13147 | B146: MR. | C146: CEDRIC | D146: LIN | E146: =B146 &" "&C146&" "&D146 -> MR. CEDRIC LIN | F146: 29456 | G146: =YEAR(F146) -> 1980 | H146: M | I146: =IF(H146="M","Married","Single") -> Married | J146: M | K146: =IF(J146="M","Male","Female") -> Male | L146: cedric8@adventure-works.com | M146: =LEFT(L146,SEARCH("@",L146)-1) -> cedric8 | N146: 30000 | O146: =IF(N146>=150000,"Wealthy",IF(N146>=100000,"Rich",IF(N146>=50000,"Average","Poor"))) -> Poor | P146: 0 | Q146: High School | R146: Skilled Manual | S146: N
A147: 13148 | B147: MR. | C147: TYLER | D147: ANDERSON | E147: =B147 &" "&C147&" "&D147 -> MR. TYLER ANDERSON | F147: 29312 | G147: =YEAR(F147) -> 1980 | H147: M | I147: =IF(H147="M","Married","Single") -> Married | J147: M | K147: =IF(J147="M","Male","Female") -> Male | L147: tyler18@adventure-works.com | M147: =LEFT(L147,SEARCH("@",L147)-1) -> tyler18 | N147: 30000 | O147: =IF(N147>=150000,"Wealthy",IF(N147>=100000,"Rich",IF(N147>=50000,"Average","Poor"))) -> Poor | P147: 0 | Q147: High School | R147: Skilled Manual | S147: Y
A148: 13149 | B148: MRS. | C148: LINDA | D148: FERRIER | E148: =B148 &" "&C148&" "&D148 -> MRS. LINDA FERRIER | F148: 16851 | G148: =YEAR(F148) -> 1946 | H148: M | I148: =IF(H148="M","Married","Single") -> Married | J148: F | K148: =IF(J148="M","Male","Female") -> Female | L148: linda23@adventure-works.com | M148: =LEFT(L148,SEARCH("@",L148)-1) -> linda23 | N148: 10000 | O148: =IF(N148>=150000,"Wealthy",IF(N148>=100000,"Rich",IF(N148>=50000,"Average","Poor"))) -> Poor | P148: 5 | Q148: High School | R148: Skilled Manual | S148: Y
A149: 13150 | B149: MRS. | C149: LACEY | D149: YANG | E149: =B149 &" "&C149&" "&D149 -> MRS. LACEY YANG | F149: 13676 | G149: =YEAR(F149) -> 1937 | H149: S | I149: =IF(H149="M","Married","Single") -> Single | J149: F | K149: =IF(J149="M","Male","Female") -> Female | L149: lacey17@adventure-works.com | M149: =LEFT(L149,SEARCH("@",L149)-1) -> lacey17 | N149: 30000 | O149: =IF(N149>=150000,"Wealthy",IF(N149>=100000,"Rich",IF(N149>=50000,"Average","Poor"))) -> Poor | P149: 2 | Q149: Partial College | R149: Clerical | S149: Y
A150: 13151 | B150: MR. | C150: ETHAN | D150: MOORE | E150: =B150 &" "&C150&" "&D150 -> MR. ETHAN MOORE | F150: 28830 | G150: =YEAR(F150) -> 1978 | H150: S | I150: =IF(H150="M","Married","Single") -> Single | J150: M | K150: =IF(J150="M","Male","Female") -> Male | L150: ethan41@adventure-works.com | M150: =LEFT(L150,SEARCH("@",L150)-1) -> ethan41 | N150: 40000 | O150: =IF(N150>=150000,"Wealthy",IF(N150>=100000,"Rich",IF(N150>=50000,"Average","Poor"))) -> Poor | P150: 0 | Q150: High School | R150: Skilled Manual | S150: Y
... A176: 11024 | B176: MR. | C176: RUSSELL | D176: XIE | E176: =B176 &" "&C176&" "&D176 -> MR. RUSSELL XIE | F176: 28750 | G176: =YEAR(F176) -> 1978 | H176: M | I176: =IF(H176="M","Married","Single") -> Married | J176: M | K176: =IF(J176="M","Male","Female") -> Male | L176: russell7@adventure-works.com | M176: =LEFT(L176,SEARCH("@",L176)-1) -> russell7 | N176: 60000 | O176: =IF(N176>=150000,"Wealthy",IF(N176>=100000,"Rich",IF(N176>=50000,"Average","Poor"))) -> Average | P176: 0 | Q176: Partial College | R176: Skilled Manual | S176: Y
A177: 11025 | C177: ALEJANDRO | D177: BECK | E177: =B177 &" "&C177&" "&D177 -> ALEJANDRO BECK | F177: 16794 | G177: =YEAR(F177) -> 1945 | H177: M | I177: =IF(H177="M","Married","Single") -> Married | J177: NA | K177: =IF(J177="M","Male","Female") -> Female | L177: alejandro45@adventure-works.com | M177: =LEFT(L177,SEARCH("@",L177)-1) -> alejandro45 | N177: 10000 | O177: =IF(N177>=150000,"Wealthy",IF(N177>=100000,"Rich",IF(N177>=50000,"Average","Poor"))) -> Poor | P177: 2 | Q177: Partial High School | R177: Clerical | S177: Y
A178: 11026 | B178: MR. | C178: HAROLD | D178: SAI | E178: =B178 &" "&C178&" "&D178 -> MR. HAROLD SAI | F178: 16895 | G178: =YEAR(F178) -> 1946 | H178: S | I178: =IF(H178="M","Married","Single") -> Single | J178: M | K178: =IF(J178="M","Male","Female") -> Male | L178: harold3@adventure-works.com | M178: =LEFT(L178,SEARCH("@",L178)-1) -> harold3 | N178: 30000 | O178: =IF(N178>=150000,"Wealthy",IF(N178>=100000,"Rich",IF(N178>=50000,"Average","Poor"))) -> Poor | P178: 2 | Q178: Partial College | R178: Clerical | S178: N
A179: 11027 | B179: MR. | C179: JESSIE | D179: ZHAO | E179: =B179 &" "&C179&" "&D179 -> MR. JESSIE ZHAO | F179: 17143 | G179: =YEAR(F179) -> 1946 | H179: M | I179: =IF(H179="M","Married","Single") -> Married | J179: M | K179: =IF(J179="M","Male","Female") -> Male | L179: jessie16@adventure-works.com | M179: =LEFT(L179,SEARCH("@",L179)-1) -> jessie16 | N179: 30000 | O179: =IF(N179>=150000,"Wealthy",IF(N179>=100000,"Rich",IF(N179>=50000,"Average","Poor"))) -> Poor | P179: 2 | Q179: Partial College | R179: Clerical | S179: Y
A180: 11028 | B180: MRS. | C180: JILL | D180: JIMENEZ | E180: =B180 &" "&C180&" "&D180 -> MRS. JILL JIMENEZ | F180: 16903 | G180: =YEAR(F180) -> 1946 | H180: M | I180: =IF(H180="M","Married","Single") -> Married | J180: F | K180: =IF(J180="M","Male","Female") -> Female | L180: jill13@adventure-works.com | M180: =LEFT(L180,SEARCH("@",L180)-1) -> jill13 | N180: 30000 | O180: =IF(N180>=150000,"Wealthy",IF(N180>=100000,"Rich",IF(N180>=50000,"Average","Poor"))) -> Poor | P180: 2 | Q180: Partial College | R180: Clerical | S180: Y
A181: 11029 | B181: MR. | C181: JIMMY | D181: MORENO | E181: =B181 &" "&C181&" "&D181 -> MR. JIMMY MORENO | F181: 17157 | G181: =YEAR(F181) -> 1946 | H181: M | I181: =IF(H181="M","Married","Single") -> Married | J181: M | K181: =IF(J181="M","Male","Female") -> Male | L181: jimmy9@adventure-works.com | M181: =LEFT(L181,SEARCH("@",L181)-1) -> jimmy9 | N181: 30000 | O181: =IF(N181>=150000,"Wealthy",IF(N181>=100000,"Rich",IF(N181>=50000,"Average","Poor"))) -> Poor | P181: 2 | Q181: Partial College | R181: Clerical | S181: Y
A182: 11030 | B182: MRS. | C182: BETHANY | D182: YUAN | E182: =B182 &" "&C182&" "&D182 -> MRS. BETHANY YUAN | F182: 17220 | G182: =YEAR(F182) -> 1947 | H182: M | I182: =IF(H182="M","Married","Single") -> Married | J182: F | K182: =IF(J182="M","Male","Female") -> Female | L182: bethany10@adventure-works.com | M182: =LEFT(L182,SEARCH("@",L182)-1) -> bethany10 | N182: 10000 | O182: =IF(N182>=150000,"Wealthy",IF(N182>=100000,"Rich",IF(N182>=50000,"Average","Poor"))) -> Poor | P182: 2 | Q182: Partial High School | R182: Clerical | S182: Y
A183: 11031 | B183: MRS. | C183: THERESA | D183: RAMOS | E183: =B183 &" "&C183&" "&D183 -> MRS. THERESA RAMOS | F183: 17401 | G183: =YEAR(F183) -> 1947 | H183: M | I183: =IF(H183="M","Married","Single") -> Married | J183: F | K183: =IF(J183="M","Male","Female") -> Female | L183: theresa13@adventure-works.com | M183: =LEFT(L183,SEARCH("@",L183)-1) -> theresa13 | N183: 20000 | O183: =IF(N183>=150000,"Wealthy",IF(N183>=100000,"Rich",IF(N183>=50000,"Average","Poor"))) -> Poor | P183: 4 | Q183: High School | R183: Skilled Manual | S183: Y
A184: 11032 | B184: MRS. | C184: DENISE | D184: STONE | E184: =B184 &" "&C184&" "&D184 -> MRS. DENISE STONE | F184: 17329 | G184: =YEAR(F184) -> 1947 | H184: M | I184: =IF(H184="M","Married","Single") -> Married | J184: F | K184: =IF(J184="M","Male","Female") -> Female | L184: denise10@adventure-works.com | M184: =LEFT(L184,SEARCH("@",L184)-1) -> denise10 | N184: 20000 | O184: =IF(N184>=150000,"Wealthy",IF(N184>=100000,"Rich",IF(N184>=50000,"Average","Poor"))) -> Poor | P184: 4 | Q184: High School | R184: Skilled Manual | S184: Y
A185: 11033 | B185: MR. | C185: JAIME | D185: NATH | E185: =B185 &" "&C185&" "&D185 -> MR. JAIME NATH | F185: 17433 | G185: =YEAR(F185) -> 1947 | H185: M | I185: =IF(H185="M","Married","Single") -> Married | J185: M | K185: =IF(J185="M","Male","Female") -> Male | L185: jaime41@adventure-works.com | M185: =LEFT(L185,SEARCH("@",L185)-1) -> jaime41 | N185: 20000 | O185: =IF(N185>=150000,"Wealthy",IF(N185>=100000,"Rich",IF(N185>=50000,"Average","Poor"))) -> Poor | P185: 4 | Q185: High School | R185: Skilled Manual | S185: Y
A186: 11034 | B186: MRS. | C186: EBONY | D186: GONZALEZ | E186: =B186 &" "&C186&" "&D186 -> MRS. EBONY GONZALEZ | F186: 17337 | G186: =YEAR(F186) -> 1947 | H186: M | I186: =IF(H186="M","Married","Single") -> Married | J186: F | K186: =IF(J186="M","Male","Female") -> Female | L186: ebony19@adventure-works.com | M186: =LEFT(L186,SEARCH("@",L186)-1) -> ebony19 | N186: 20000 | O186: =IF(N186>=150000,"Wealthy",IF(N186>=100000,"Rich",IF(N186>=50000,"Average","Poor"))) -> Poor | P186: 4 | Q186: High School | R186: Skilled Manual | S186: Y
A187: 11035 | C187: WENDY | D187: DOMINGUEZ | E187: =B187 &" "&C187&" "&D187 -> WENDY DOMINGUEZ | F187: 17587 | G187: =YEAR(F187) -> 1948 | H187: M | I187: =IF(H187="M","Married","Single") -> Married | J187: NA | K187: =IF(J187="M","Male","Female") -> Female | L187: wendy12@adventure-works.com | M187: =LEFT(L187,SEARCH("@",L187)-1) -> wendy12 | N187: 10000 | O187: =IF(N187>=150000,"Wealthy",IF(N187>=100000,"Rich",IF(N187>=50000,"Average","Poor"))) -> Poor | P187: 2 | Q187: Partial High School | R187: Clerical | S187: Y
A188: 11036 | B188: MS. | C188: JENNIFER | D188: RUSSELL | E188: =B188 &" "&C188&" "&D188 -> MS. JENNIFER RUSSELL | F188: 28842 | G188: =YEAR(F188) -> 1978 | H188: M | I188: =IF(H188="M","Married","Single") -> Married | J188: F | K188: =IF(J188="M","Male","Female") -> Female | L188: jennifer93@adventure-works.com | M188: =LEFT(L188,SEARCH("@",L188)-1) -> jennifer93 | N188: 60000 | O188: =IF(N188>=150000,"Wealthy",IF(N188>=100000,"Rich",IF(N188>=50000,"Average","Poor"))) -> Average | P188: 0 | Q188: Partial College | R188: Skilled Manual | S188: Y
...

Sheet Sheet1
A1: How many customers fall into each wealth category (Rich, Average, Poor), grouped by their marital status (Single, Married)?
A3: Count of Wealth Category | B3: Column Labels
A4: Row Labels | B4: M | C4: S | D4: Grand Total
A5: Average | B5: 73 | C5: 83 | D5: 156
A6: Poor | B6: 74 | C6: 67 | D6: 141
A7: Rich | B7: 13 | C7: 15 | D7: 28
A8: Wealthy | B8: 1 | C8: 1 | D8: 2
A9: Grand Total | B9: 161 | C9: 166 | D9: 327
A12: How many male vs. female customers own a home versus those who don’t?
A14: Count of HomeOwner | B14: Column Labels
A15: Row Labels | B15: N | C15: Y | D15: (blank) | E15: Grand Total
A16: Female | B16: 67 | C16: 93 | E16: 160
A17: Male | B17: 61 | C17: 106 | E17: 167
A18: (blank)
A19: Grand Total | B19: 128 | C19: 199 | E19: 327
A22: Which occupations contribute the highest total annual income?
B24: Column Labels
B25: Clerical | D25: Management | F25: Professional | H25: Skilled Manual | J25: Total Count of Occupation | K25: Total Sum of AnnualIncome
A26: Row Labels | B26: Count of Occupation | C26: Sum of AnnualIncome | D26: Count of Occupation | E26: Sum of AnnualIncome | F26: Count of Occupation | G26: Sum of AnnualIncome | H26: Count of Occupation | I26: Sum of AnnualIncome
A27: 10000 | B27: 7 | C27: 70000 | H27: 4 | I27: 40000 | J27: 11 | K27: 110000
A28: 20000 | B28: 2 | C28: 40000 | H28: 7 | I28: 140000 | J28: 9 | K28: 180000
A29: 30000 | B29: 18 | C29: 540000 | F29: 1 | G29: 30000 | H29: 37 | I29: 1110000 | J29: 56 | K29: 1680000
A30: 40000 | B30: 5 | C30: 200000 | D30: 6 | E30: 240000 | F30: 1 | G30: 40000 | H30: 53 | I30: 2120000 | J30: 65 | K30: 2600000
A31: 50000 | D31: 1 | E31: 50000 | J31: 1 | K31: 50000
A32: 60000 | D32: 2 | E32: 120000 | F32: 29 | G32: 1740000 | H32: 22 | I32: 1320000 | J32: 53 | K32: 3180000
A33: 70000 | D33: 1 | E33: 70000 | F33: 30 | G33: 2100000 | H33: 21 | I33: 1470000 | J33: 52 | K33: 3640000
A34: 80000 | D34: 8 | E34: 640000 | F34: 11 | G34: 880000 | H34: 17 | I34: 1360000 | J34: 36 | K34: 2880000
A35: 90000 | D35: 3 | E35: 270000 | F35: 11 | G35: 990000 | J35: 14 | K35: 1260000
A36: 100000 | D36: 9 | E36: 900000 | F36: 3 | G36: 300000 | J36: 12 | K36: 1200000
A37: 110000 | D37: 7 | E37: 770000 | J37: 7 | K37: 770000
A38: 120000 | D38: 2 | E38: 240000 | J38: 2 | K38: 240000
A39: 130000 | D39: 7 | E39: 910000 | J39: 7 | K39: 910000
A40: 160000 | D40: 1 | E40: 160000 | J40: 1 | K40: 160000
A41: 170000 | D41: 1 | E41: 170000 | J41: 1 | K41: 170000
A42: Grand Total | B42: 32 | C42: 850000 | D42: 48 | E42: 4540000 | F42: 86 | G42: 6080000 | H42: 161 | I42: 7560000 | J42: 327 | K42: 19030000
A45: What is the average number of children per customer, grouped by wealth category?
A47: Row Labels | B47: Count of BirthDate
A48: Female | B48: 160
A49: Male | B49: 167
A50: (blank)
...

Sheet Dashboard
J37: Row Labels | K37: Count of BirthDate
J38: Female | K38: 160
J39: Male | K39: 167
J40: Grand Total | K40: 327

Sheet Summary
A1: Customer Summary
A2: Total Customers | B2: =COUNTA(Customers!A2:A328) -> 327
A3: 1956 | B3: =COUNTIF(Customers!G2:G328,"1956") -> 6
A4: Single | B4: =COUNTIF(Customers!I2:I328,"single") -> 166
A5: Female | B5: =COUNTIF(Customers!K2:K328,"female") -> 160
A6: Total Annual Income | B6: =SUM(Customers!N2:N328) -> 19030000
A7: Average Annual Income | B7: =AVERAGE(Customers!N2:N32) -> 56451.613
A8: Rich | B8: =COUNTIF(Customers!O2:O328,"rich") -> 28
A9: High School | B9: =COUNTIF(Customers!Q2:Q328,"High School") -> 98
A10: Male Bachelors | B10: =COUNTIF(Customers!Q2:Q328,"Bachelors") -> 78
A11: Graduate Degree | B11: =COUNTIF(Customers!Q2:Q328,"Graduate Degree") -> 26
A12: Professional (90000) | B12: =COUNTIFS(Customers!R2:R328,"Professional",Customers!N2:N328,">90000") -> 3
A13: Clerical | B13: =COUNTIF(Customers!R2:R328,"Clerical") -> 32
